Workbook
Name Slicer_Month: #N/A
Name Slicer_Payment_Mode: #N/A
Name Slicer_Product_Category: #N/A
Name Slicer_State: #N/A

Sheet Raw_Data
A1: Order_ID | B1: Order_Date | C1: Dispatch_Date | D1: Delivery_Date | E1: Customer_Name | F1: City | G1: State | H1: Product_Category | I1: Product_Name | J1: Quantity | K1: Unit_Price | L1: Total_Amount | M1: Payment_Mode | N1: Order_Status | O1: Delivery_Status | P1: Warehouse | Q1: Sales_Channel | R1: Return_Flag | S1: Return_Reason | T1: Delivery_Days
A2: ORD00001 | B2: 2024-10-26 | C2: 2024-10-27 | D2: 2024-10-28 | E2: Karan Gupta | F2: hyderabad | G2: Telangana | H2: Furniture | I2: Sofa | J2: 2 | K2: 100 | L2: 200 | M2: Card | N2: Pending | O2: Delayed | P2: WH-Delhi | Q2: Online | R2: No | T2: 1
A3: ORD00002 | B3: 2024-07-19 | C3: 2024-07-20 | D3: 2024-07-26 | E3: Sneha Singh | F3: PUNE | G3: Maharashtra | H3: Grocery | I3: Oil | J3: 3 | K3: 2000 | L3: 6000 | M3: Card | N3: Pending | O3: On Time | P3: WH-Delhi | Q3: Offline | R3: Yes | S3: Late Delivery | T3: 6
A4: ORD00003 | B4: 2024-10-09 | C4: 2024-10-07 | D4: 2024-10-13 | E4: Karan Yadav | F4: Jaipur | G4: Rajasthan | H4: Furniture | I4: Table | J4: 1 | K4: 500 | L4: 500 | M4: UPI | N4: Completed | O4: Delayed | P4: WH-Pune | Q4: Online | R4: Yes | T4: 6
A5: ORD00004 | B5: 2024-02-27 | C5: 2024-02-26 | D5: 2024-02-27 | E5: Neha Sharma | F5: PUNE | G5: Maharashtra | H5: Furniture | I5: Table | J5: 1 | K5: 2000 | L5: 2000 | M5: Cash | N5: Completed | O5: delayed | P5: WH-Delhi | Q5: Online | R5: No | T5: 1
A6: ORD00005 | B6: 2024-07-29 | C6: 2024-07-30 | D6: 2024-07-30 | E6: Rahul Singh | F6: Bangalore | G6: Karnataka | H6: Clothing | I6: Jeans | J6: 1 | K6: 0 | L6: 0 | M6: Card | N6: completed | O6: delayed | P6: WH-Delhi | Q6: Offline | R6: Yes | T6: 0
A7: ORD00006 | B7: 2024-06-25 | C7: 2024-06-25 | D7: 2024-06-29 | E7: Vikas Joshi | F7: Jaipur | G7: Rajasthan | H7: Grocery | I7: Rice | J7: -1 | K7: 500 | L7: -500 | M7: Cash | N7: Completed | O7: In Transit | P7: WH-Delhi | Q7: Online | R7: No | T7: 4
A8: ORD00007 | B8: 2024-01-05 | C8: 2024-01-07 | D8: 2024-01-08 | E8: Karan Yadav | F8: Jaipur | G8: Rajasthan | H8: Furniture | I8: Chair | J8: 0 | K8: 2000 | L8: 0 | M8: UPI | N8: completed | O8: delayed | P8: WH-Mumbai | Q8: Online | R8: No | T8: 1
A9: ORD00008 | B9: 2024-11-16 | C9: 2024-11-18 | D9: 2024-11-20 | E9: Sneha Patel | F9: nagpur | G9: Maharashtra | H9: Clothing | I9: T-Shirt | J9: 1 | K9: 0 | L9: 0 | M9: Card | N9: Cancelled | O9: On Time | P9: WH-Pune | Q9: Online | T9: 2
A10: ORD00009 | B10: 2024-02-24 | C10: 2024-02-22 | D10: 2024-02-27 | E10: Rahul Joshi | F10: Bangalore | G10: Karnataka | H10: Clothing | I10: T-Shirt | J10: 2 | K10: 100 | L10: 200 | M10: UPI | N10: Completed | O10: On Time | P10: WH-Pune | Q10: Online | T10: 5
A11: ORD00010 | B11: 2024-12-15 | C11: 2024-12-18 | D11: 2024-12-18 | E11: Rahul Singh | F11: PUNE | G11: Maharashtra | H11: Furniture | I11: Sofa | J11: -1 | K11: 1000 | L11: -1000 | N11: completed | O11: delayed | P11: WH-Pune | Q11: Online | R11: Yes | S11: Late Delivery | T11: 0
A12: ORD00011 | B12: 2024-10-14 | C12: 2024-10-13 | D12: 2024-10-12 | E12: Vikas Yadav | F12: hyderabad | G12: Telangana | H12: Grocery | I12: Oil | J12: 2 | K12: 2000 | L12: 4000 | N12: Completed | O12: Delayed | P12: WH-Pune | Q12: Online | R12: No | T12: -1
A13: ORD00012 | B13: 2024-06-22 | C13: 2024-06-20 | D13: 2024-06-21 | E13: Amit Gupta | F13: PUNE | G13: Maharashtra | H13: Furniture | I13: Sofa | J13: 0 | K13: 0 | L13: 295 | M13: Card | N13: Cancelled | O13: Delayed | P13: WH-Mumbai | Q13: Online | R13: Yes | S13: Late Delivery | T13: 1
A14: ORD00013 | B14: 2024-07-27 | C14: 2024-07-28 | D14: 2024-08-01 | E14: Sneha Kumar | F14: lucknow | G14: Uttar Pradesh | H14: Clothing | I14: Jacket | J14: 2 | K14: 500 | L14: 1000 | M14: UPI | N14: Completed | O14: On Time | P14: WH-Pune | Q14: Online | R14: No | T14: 4
A15: ORD00014 | B15: 2024-09-12 | C15: 2024-09-15 | D15: 2024-09-14 | E15: Neha Sharma | F15: nagpur | G15: Maharashtra | H15: Grocery | I15: Wheat | J15: -1 | K15: 1000 | L15: -1000 | N15: Pending | O15: delayed | P15: WH-Pune | Q15: Offline | T15: -1
A16: ORD00015 | B16: 2024-12-31 | C16: 2025-01-01 | D16: 2025-01-08 | E16: Vikas Patel | F16: PUNE | G16: Maharashtra | H16: Electronics | I16: Headphones | J16: 2 | K16: 100 | L16: 200 | M16: Cash | N16: Completed | O16: Delayed | P16: WH-Pune | Q16: Online | R16: Yes | T16: 7
A17: ORD00016 | B17: 2024-11-19 | C17: 2024-11-21 | D17: 2024-11-26 | E17: Anjali Singh | F17: hyderabad | G17: Telangana | H17: Clothing | I17: Jacket | J17: 2 | K17: 1000 | L17: 2000 | M17: Card | N17: completed | O17: Delayed | P17: WH-Pune | Q17: Online | R17: No | T17: 5
A18: ORD00017 | B18: 2024-02-20 | C18: 2024-02-21 | D18: 2024-02-22 | E18: Anjali Verma | F18: lucknow | G18: Uttar Pradesh | H18: Clothing | I18: T-Shirt | J18: 1 | K18: 1000 | L18: 1000 | M18: UPI | N18: Cancelled | O18: In Transit | P18: WH-Delhi | Q18: Offline | R18: No | T18: 1
A19: ORD00018 | B19: 2024-06-24 | C19: 2024-06-24 | D19: 2024-06-29 | E19: Rohit Kumar | F19: lucknow | G19: Uttar Pradesh | H19: Furniture | I19: Chair | J19: 3 | K19: 100 | L19: 300 | M19: UPI | N19: Completed | O19: On Time | P19: WH-Delhi | Q19: Offline | R19: No | T19: 5
A20: ORD00019 | B20: 2024-10-21 | C20: 2024-10-22 | D20: 2024-10-23 | E20: Vikas Joshi | F20: delhi | G20: Delhi | H20: Clothing | I20: Jacket | J20: 1 | K20: 100 | L20: 100 | M20: Cash | N20: Pending | O20: Delayed | P20: WH-Delhi | Q20: Online | R20: No | T20: 1
A21: ORD00020 | B21: 2024-03-06 | C21: 2024-03-06 | D21: 2024-03-05 | E21: Sneha Kumar | F21: Jaipur | G21: Rajasthan | H21: Clothing | I21: T-Shirt | J21: 1 | K21: 0 | L21: 0 | M21: Cash | N21: Cancelled | O21: On Time | P21: WH-Delhi | Q21: Online | R21: Yes | S21: Late Delivery | T21: -1
A22: ORD00021 | B22: 2024-01-22 | C22: 2024-01-21 | D22: 2024-01-21 | E22: Priya Singh | F22: lucknow | G22: Uttar Pradesh | H22: Electronics | I22: Headphones | J22: 3 | K22: 500 | L22: 1500 | M22: UPI | N22: Cancelled | O22: In Transit | P22: WH-Mumbai | Q22: Online | T22: 0
A23: ORD00022 | B23: 2024-05-23 | C23: 2024-05-21 | D23: 2024-05-20 | E23: Priya Singh | F23: hyderabad | G23: Telangana | H23: Clothing | I23: Jacket | J23: 3 | K23: 2000 | L23: 6000 | N23: completed | O23: delayed | P23: WH-Mumbai | Q23: Offline | T23: -1
A24: ORD00023 | B24: 2024-06-12 | C24: 2024-06-15 | D24: 2024-06-18 | E24: Pooja Verma | F24: delhi | G24: Delhi | H24: Clothing | I24: T-Shirt | J24: -1 | K24: 100 | L24: -131 | M24: Cash | N24: completed | O24: Delayed | P24: WH-Pune | Q24: Online | T24: 3
A25: ORD00024 | B25: 2024-04-17 | C25: 2024-04-17 | D25: 2024-04-19 | E25: Rahul Kumar | F25: Mumbai | G25: Maharashtra | H25: Electronics | I25: Laptop | J25: 3 | K25: 1000 | L25: 2979 | M25: Cash | N25: Completed | O25: In Transit | P25: WH-Mumbai | Q25: Offline | R25: No | T25: 2
A26: ORD00025 | B26: 2024-10-07 | C26: 2024-10-06 | D26: 2024-10-07 | E26: Sneha Sharma | F26: delhi | G26: Delhi | H26: Grocery | I26: Rice | J26: 0 | K26: 100 | L26: 0 | M26: Cash | N26: Cancelled | O26: In Transit | P26: WH-Pune | Q26: Offline | R26: Yes | S26: Late Delivery | T26: 1
A27: ORD00026 | B27: 2024-01-21 | C27: 2024-01-23 | D27: 2024-01-29 | E27: Amit Yadav | F27: Bangalore | G27: Karnataka | H27: Electronics | I27: Headphones | J27: -1 | K27: 100 | L27: -2 | M27: Card | N27: Completed | O27: Delayed | P27: WH-Mumbai | Q27: Offline | R27: No | T27: 6
A28: ORD00027 | B28: 2024-05-15 | C28: 2024-05-18 | D28: 2024-05-25 | E28: Vikas Verma | F28: hyderabad | G28: Telangana | H28: Clothing | I28: Jeans | J28: 0 | K28: 100 | L28: 0 | M28: Cash | N28: Cancelled | O28: In Transit | P28: WH-Pune | Q28: Online | T28: 7
A29: ORD00028 | B29: 2024-11-11 | C29: 2024-11-12 | D29: 2024-11-17 | E29: Rahul Yadav | F29: Jaipur | G29: Rajasthan | H29: Electronics | I29: Headphones | J29: 2 | K29: 2000 | L29: 4000 | M29: UPI | N29: completed | O29: In Transit | P29: WH-Delhi | Q29: Offline | T29: 5
A30: ORD00029 | B30: 2024-10-07 | C30: 2024-10-05 | D30: 2024-10-08 | E30: Priya Verma | F30: Jaipur | G30: Rajasthan | H30: Electronics | I30: Laptop | J30: 1 | K30: 100 | L30: 100 | M30: Cash | N30: Cancelled | O30: On Time | P30: WH-Mumbai | Q30: Offline | T30: 3
A31: ORD00030 | B31: 2024-05-26 | C31: 2024-05-27 | D31: 2024-05-26 | E31: Anjali Yadav | F31: Bangalore | G31: Karnataka | H31: Clothing | I31: Jeans | J31: 0 | K31: 2000 | L31: 0 | M31: Card | N31: Cancelled | O31: On Time | P31: WH-Delhi | Q31: Offline | R31: No | T31: -1
A32: ORD00031 | B32: 2024-10-26 | C32: 2024-10-29 | D32: 2024-11-04 | E32: Rahul Yadav | F32: PUNE | G32: Maharashtra | H32: Grocery | I32: Oil | J32: 0 | K32: 2000 | L32: 0 | M32: UPI | N32: Completed | O32: On Time | P32: WH-Mumbai | Q32: Offline | R32: No | T32: 6
A33: ORD00032 | B33: 2024-09-17 | C33: 2024-09-19 | D33: 2024-09-23 | E33: Anjali Singh | F33: nagpur | G33: Maharashtra | H33: Clothing | I33: Jacket | J33: 3 | K33: 500 | L33: 1500 | M33: UPI | N33: completed | O33: Delayed | P33: WH-Mumbai | Q33: Online | R33: No | T33: 4
A34: ORD00033 | B34: 2024-11-09 | C34: 2024-11-10 | D34: 2024-11-11 | E34: Sneha Gupta | F34: delhi | G34: Delhi | H34: Clothing | I34: Jeans | J34: 2 | K34: 2000 | L34: 4000 | M34: Cash | N34: Completed | O34: In Transit | P34: WH-Delhi | Q34: Offline | R34: No | T34: 1
A35: ORD00034 | B35: 2024-07-25 | C35: 2024-07-26 | D35: 2024-07-26 | E35: Sneha Kumar | F35: PUNE | G35: Maharashtra | H35: Grocery | I35: Rice | J35: 3 | K35: 1000 | L35: 3000 | M35: Card | N35: Completed | O35: Delayed | P35: WH-Delhi | Q35: Online | T35: 0
A36: ORD00035 | B36: 2024-05-02 | C36: 2024-05-03 | D36: 2024-05-08 | E36: Sneha Kumar | F36: hyderabad | G36: Telangana | H36: Clothing | I36: Jeans | J36: 1 | K36: 1000 | L36: 1000 | N36: Cancelled | O36: delayed | P36: WH-Pune | Q36: Online | R36: No | T36: 5
A37: ORD00036 | B37: 2024-03-25 | C37: 2024-03-27 | D37: 2024-03-31 | E37: Pooja Patel | F37: lucknow | G37: Uttar Pradesh | H37: Grocery | I37: Oil | J37: 2 | K37: 2000 | L37: 4000 | N37: Completed | O37: On Time | P37: WH-Pune | Q37: Offline | T37: 4
A38: ORD00037 | B38: 2024-07-31 | C38: 2024-08-03 | D38: 2024-08-05 | E38: Pooja Kumar | F38: Jaipur | G38: Rajasthan | H38: Clothing | I38: T-Shirt | J38: 1 | K38: 2000 | L38: 2000 | M38: Cash | N38: completed | O38: Delayed | P38: WH-Delhi | Q38: Online | R38: No | T38: 2
A39: ORD00038 | B39: 2024-06-22 | C39: 2024-06-24 | D39: 2024-06-24 | E39: Anjali Verma | F39: delhi | G39: Delhi | H39: Furniture | I39: Chair | J39: 0 | K39: 2000 | L39: 0 | M39: UPI | N39: Pending | O39: In Transit | P39: WH-Delhi | Q39: Online | R39: No | T39: 0
A40: ORD00039 | B40: 2024-06-06 | C40: 2024-06-04 | D40: 2024-06-10 | E40: Amit Verma | F40: Bangalore | G40: Karnataka | H40: Grocery | I40: Wheat | J40: 2 | K40: 2000 | L40: 4000 | M40: Cash | N40: completed | O40: Delayed | P40: WH-Delhi | Q40: Online | R40: No | T40: 6
...

Sheet Clean_data
A1: Order_ID | B1: Order_Date | C1: Dispatch_Date | D1: Delivery_Date | E1: Customer_Name | F1: City | G1: State | H1: Product_Category | I1: Product_Name | J1: Quantity | K1: Unit_Price | L1: Total_Amount | M1: Payment_Mode | N1: Order_Status | O1: Delivery_Status | P1: Warehouse | Q1: Sales_Channel | R1: Return_Flag | S1: Return_Reason | T1: Delivery_Days | U1: Duplicate check | V1: Qty_Check_Status | W1: Unit_Price_Status | X1: Date_Status | Y1: Price_Check | Z1: Amount check | AA1: Final_Amount | AB1: Payment_Mode_check | AC1: Final_return_flag
A2: ORD00001 | B2: {=DATEVALUE(VLOOKUP(A2,Raw_Data!A1:D2001,{2,3,4},0))} -> 45591 | C2: 45592 | D2: 45593 | E2: Karan Gupta | F2: Hyderabad | G2: Telangana | H2: Furniture | I2: Sofa | J2: 2 | K2: 100 | L2: =J2*K2 -> 200 | M2: Card | N2: Pending | O2: Delayed | P2: WH-Delhi | Q2: Online | R2: No | S2: Late Delivery | T2: 1 | U2: =IF(COUNTIF(A2:A2001,A2)=1,"Keep","Duplicate") -> Keep | V2: =IF(J2<=0,"Fix","Ok") -> Ok | W2: =IF(Raw_Data!K2=0,"Missing","Valid") -> Valid | X2: =IF(C2<B2,"Dispatch Error",IF(D2<B2,"Delivery Before Order",IF(D2<C2,"Delivery Before Dispatch","OK"))) -> OK | Y2: =IF(K2<=0,"Fix","Ok") -> Ok | Z2: =IF(L2="","Blank",IF(L2=J2*K2,"Ok","Wrong")) -> Ok | AA2: =IF(OR(L2="",L2<>J2*K2),J2*K2,L2) -> 200 | AB2: =IF(M2="","Missing","ok") -> ok | AC2: =IF(R2="No","Not Returned",IF(R2="Yes",IF(S2="","Unknown",S2),IF(L2<0,"Wrong",IF(OR(O2="Delayed",O2="In Transit",O2="On Time"),"Not Returned","")))) -> Not Returned
A3: ORD00002 | B3: {=DATEVALUE(VLOOKUP(A3,Raw_Data!A2:D2002,{2,3,4},0))} -> 45492 | C3: 45493 | D3: 45499 | E3: Sneha Singh | F3: Pune | G3: Maharashtra | H3: Grocery | I3: Oil | J3: 3 | K3: 2000 | L3: =J3*K3 -> 6000 | M3: Card | N3: Pending | O3: On Time | P3: WH-Delhi | Q3: Offline | R3: Yes | S3: Late Delivery | T3: 6 | U3: =IF(COUNTIF(A3:A2002,A3)=1,"Keep","Duplicate") -> Keep | V3: =IF(J3<=0,"Fix","Ok") -> Ok | W3: =IF(Raw_Data!K3=0,"Missing","Valid") -> Valid | X3: =IF(C3<B3,"Dispatch Error",IF(D3<B3,"Delivery Before Order",IF(D3<C3,"Delivery Before Dispatch","OK"))) -> OK | Y3: =IF(K3<=0,"Fix","Ok") -> Ok | Z3: =IF(L3="","Blank",IF(L3=J3*K3,"Ok","Wrong")) -> Ok | AA3: =IF(OR(L3="",L3<>J3*K3),J3*K3,L3) -> 6000 | AB3: =IF(M3="","Missing","ok") -> ok | AC3: =IF(R3="No","Not Returned",IF(R3="Yes",IF(S3="","Unknown",S3),IF(L3<0,"Wrong",IF(OR(O3="Delayed",O3="In Transit",O3="On Time"),"Not Returned","")))) -> Late Delivery
A4: ORD00003 | B4: {=DATEVALUE(VLOOKUP(A4,Raw_Data!A3:D2003,{2,3,4},0))} -> 45574 | C4: 45572 | D4: 45578 | E4: Karan Yadav | F4: Jaipur | G4: Rajasthan | H4: Furniture | I4: Table | J4: 1 | K4: 500 | L4: =J4*K4 -> 500 | M4: UPI | N4: Completed | O4: Delayed | P4: WH-Pune | Q4: Online | R4: Yes | S4: Late Delivery | T4: 6 | U4: =IF(COUNTIF(A4:A2003,A4)=1,"Keep","Duplicate") -> Keep | V4: =IF(J4<=0,"Fix","Ok") -> Ok | W4: =IF(Raw_Data!K4=0,"Missing","Valid") -> Valid | X4: =IF(C4<B4,"Dispatch Error",IF(D4<B4,"Delivery Before Order",IF(D4<C4,"Delivery Before Dispatch","OK"))) -> Dispatch Error | Y4: =IF(K4<=0,"Fix","Ok") -> Ok | Z4: =IF(L4="","Blank",IF(L4=J4*K4,"Ok","Wrong")) -> Ok | AA4: =IF(OR(L4="",L4<>J4*K4),J4*K4,L4) -> 500 | AB4: =IF(M4="","Missing","ok") -> ok | AC4: =IF(R4="No","Not Returned",IF(R4="Yes",IF(S4="","Unknown",S4),IF(L4<0,"Wrong",IF(OR(O4="Delayed",O4="In Transit",O4="On Time"),"Not Returned","")))) -> Late Delivery
A5: ORD00004 | B5: {=DATEVALUE(VLOOKUP(A5,Raw_Data!A4:D2004,{2,3,4},0))} -> 45349 | C5: 45348 | D5: 45349 | E5: Neha Sharma | F5: Pune | G5: Maharashtra | H5: Furniture | I5: Table | J5: 1 | K5: 2000 | L5: =J5*K5 -> 2000 | M5: Cash | N5: Completed | O5: Delayed | P5: WH-Delhi | Q5: Online | R5: No | S5: Late Delivery | T5: 1 | U5: =IF(COUNTIF(A5:A2004,A5)=1,"Keep","Duplicate") -> Keep | V5: =IF(J5<=0,"Fix","Ok") -> Ok | W5: =IF(Raw_Data!K5=0,"Missing","Valid") -> Valid | X5: =IF(C5<B5,"Dispatch Error",IF(D5<B5,"Delivery Before Order",IF(D5<C5,"Delivery Before Dispatch","OK"))) -> Dispatch Error | Y5: =IF(K5<=0,"Fix","Ok") -> Ok | Z5: =IF(L5="","Blank",IF(L5=J5*K5,"Ok","Wrong")) -> Ok | AA5: =IF(OR(L5="",L5<>J5*K5),J5*K5,L5) -> 2000 | AB5: =IF(M5="","Missing","ok") -> ok | AC5: =IF(R5="No","Not Returned",IF(R5="Yes",IF(S5="","Unknown",S5),IF(L5<0,"Wrong",IF(OR(O5="Delayed",O5="In Transit",O5="On Time"),"Not Returned","")))) -> Not Returned
A6: ORD00005 | B6: {=DATEVALUE(VLOOKUP(A6,Raw_Data!A5:D2005,{2,3,4},0))} -> 45502 | C6: 45503 | D6: 45503 | E6: Rahul Singh | F6: Bangalore | G6: Karnataka | H6: Clothing | I6: Jeans | J6: 1 | K6: 0 | L6: =J6*K6 -> 0 | M6: Card | N6: Completed | O6: delayed | P6: WH-Delhi | Q6: Offline | R6: Yes | S6: Late Delivery | T6: 0 | U6: =IF(COUNTIF(A6:A2005,A6)=1,"Keep","Duplicate") -> Keep | V6: =IF(J6<=0,"Fix","Ok") -> Ok | W6: =IF(Raw_Data!K6=0,"Missing","Valid") -> Missing | X6: =IF(C6<B6,"Dispatch Error",IF(D6<B6,"Delivery Before Order",IF(D6<C6,"Delivery Before Dispatch","OK"))) -> OK | Y6: =IF(K6<=0,"Fix","Ok") -> Fix | Z6: =IF(L6="","Blank",IF(L6=J6*K6,"Ok","Wrong")) -> Ok | AA6: =IF(OR(L6="",L6<>J6*K6),J6*K6,L6) -> 0 | AB6: =IF(M6="","Missing","ok") -> ok | AC6: =IF(R6="No","Not Returned",IF(R6="Yes",IF(S6="","Unknown",S6),IF(L6<0,"Wrong",IF(OR(O6="Delayed",O6="In Transit",O6="On Time"),"Not Returned","")))) -> Late Delivery
A7: ORD00006 | B7: {=DATEVALUE(VLOOKUP(A7,Raw_Data!A6:D2006,{2,3,4},0))} -> 45468 | C7: 45468 | D7: 45472 | E7: Vikas Joshi | F7: Jaipur | G7: Rajasthan | H7: Grocery | I7: Rice | J7: -1 | K7: 500 | L7: =J7*K7 -> -500 | M7: Cash | N7: Completed | O7: In Transit | P7: WH-Delhi | Q7: Online | R7: No | S7: Late Delivery | T7: 4 | U7: =IF(COUNTIF(A7:A2006,A7)=1,"Keep","Duplicate") -> Keep | V7: =IF(J7<=0,"Fix","Ok") -> Fix | W7: =IF(Raw_Data!K7=0,"Missing","Valid") -> Valid | X7: =IF(C7<B7,"Dispatch Error",IF(D7<B7,"Delivery Before Order",IF(D7<C7,"Delivery Before Dispatch","OK"))) -> OK | Y7: =IF(K7<=0,"Fix","Ok") -> Ok | Z7: =IF(L7="","Blank",IF(L7=J7*K7,"Ok","Wrong")) -> Ok | AA7: =IF(OR(L7="",L7<>J7*K7),J7*K7,L7) -> -500 | AB7: =IF(M7="","Missing","ok") -> ok | AC7: =IF(R7="No","Not Returned",IF(R7="Yes",IF(S7="","Unknown",S7),IF(L7<0,"Wrong",IF(OR(O7="Delayed",O7="In Transit",O7="On Time"),"Not Returned","")))) -> Not Returned
A8: ORD00007 | B8: {=DATEVALUE(VLOOKUP(A8,Raw_Data!A7:D2007,{2,3,4},0))} -> 45296 | C8: 45298 | D8: 45299 | E8: Karan Yadav | F8: Jaipur | G8: Rajasthan | H8: Furniture | I8: Chair | J8: 0 | K8: 2000 | L8: =J8*K8 -> 0 | M8: UPI | N8: Completed | O8: Delayed | P8: WH-Mumbai | Q8: Online | R8: No | S8: Late Delivery | T8: 1 | U8: =IF(COUNTIF(A8:A2007,A8)=1,"Keep","Duplicate") -> Keep | V8: =IF(J8<=0,"Fix","Ok") -> Fix | W8: =IF(Raw_Data!K8=0,"Missing","Valid") -> Valid | X8: =IF(C8<B8,"Dispatch Error",IF(D8<B8,"Delivery Before Order",IF(D8<C8,"Delivery Before Dispatch","OK"))) -> OK | Y8: =IF(K8<=0,"Fix","Ok") -> Ok | Z8: =IF(L8="","Blank",IF(L8=J8*K8,"Ok","Wrong")) -> Ok | AA8: =IF(OR(L8="",L8<>J8*K8),J8*K8,L8) -> 0 | AB8: =IF(M8="","Missing","ok") -> ok | AC8: =IF(R8="No","Not Returned",IF(R8="Yes",IF(S8="","Unknown",S8),IF(L8<0,"Wrong",IF(OR(O8="Delayed",O8="In Transit",O8="On Time"),"Not Returned","")))) -> Not Returned
A9: ORD00008 | B9: {=DATEVALUE(VLOOKUP(A9,Raw_Data!A8:D2008,{2,3,4},0))} -> 45612 | C9: 45614 | D9: 45616 | E9: Sneha Patel | F9: Nagpur | G9: Maharashtra | H9: Clothing | I9: T-Shirt | J9: 1 | K9: 0 | L9: =J9*K9 -> 0 | M9: Card | N9: Cancelled | O9: On Time | P9: WH-Pune | Q9: Online | R9: yes | S9: Late Delivery | T9: 2 | U9: =IF(COUNTIF(A9:A2008,A9)=1,"Keep","Duplicate") -> Keep | V9: =IF(J9<=0,"Fix","Ok") -> Ok | W9: =IF(Raw_Data!K9=0,"Missing","Valid") -> Missing | X9: =IF(C9<B9,"Dispatch Error",IF(D9<B9,"Delivery Before Order",IF(D9<C9,"Delivery Before Dispatch","OK"))) -> OK | Y9: =IF(K9<=0,"Fix","Ok") -> Fix | Z9: =IF(L9="","Blank",IF(L9=J9*K9,"Ok","Wrong")) -> Ok | AA9: =IF(OR(L9="",L9<>J9*K9),J9*K9,L9) -> 0 | AB9: =IF(M9="","Missing","ok") -> ok | AC9: =IF(R9="No","Not Returned",IF(R9="Yes",IF(S9="","Unknown",S9),IF(L9<0,"Wrong",IF(OR(O9="Delayed",O9="In Transit",O9="On Time"),"Not Returned","")))) -> Late Delivery
A10: ORD00009 | B10: {=DATEVALUE(VLOOKUP(A10,Raw_Data!A9:D2009,{2,3,4},0))} -> 45346 | C10: 45344 | D10: 45349 | E10: Rahul Joshi | F10: Bangalore | G10: Karnataka | H10: Clothing | I10: T-Shirt | J10: 2 | K10: 100 | L10: =J10*K10 -> 200 | M10: UPI | N10: Completed | O10: On Time | P10: WH-Pune | Q10: Online | R10: yes | S10: Late Delivery | T10: 5 | U10: =IF(COUNTIF(A10:A2009,A10)=1,"Keep","Duplicate") -> Keep | V10: =IF(J10<=0,"Fix","Ok") -> Ok | W10: =IF(Raw_Data!K10=0,"Missing","Valid") -> Valid | X10: =IF(C10<B10,"Dispatch Error",IF(D10<B10,"Delivery Before Order",IF(D10<C10,"Delivery Before Dispatch","OK"))) -> Dispatch Error | Y10: =IF(K10<=0,"Fix","Ok") -> Ok | Z10: =IF(L10="","Blank",IF(L10=J10*K10,"Ok","Wrong")) -> Ok | AA10: =IF(OR(L10="",L10<>J10*K10),J10*K10,L10) -> 200 | AB10: =IF(M10="","Missing","ok") -> ok | AC10: =IF(R10="No","Not Returned",IF(R10="Yes",IF(S10="","Unknown",S10),IF(L10<0,"Wrong",IF(OR(O10="Delayed",O10="In Transit",O10="On Time"),"Not Returned","")))) -> Late Delivery
A11: ORD00010 | B11: {=DATEVALUE(VLOOKUP(A11,Raw_Data!A10:D2010,{2,3,4},0))} -> 45641 | C11: 45644 | D11: 45644 | E11: Rahul Singh | F11: Pune | G11: Maharashtra | H11: Furniture | I11: Sofa | J11: -1 | K11: 1000 | L11: =J11*K11 -> -1000 | M11: Unknown | N11: Completed | O11: Delayed | P11: WH-Pune | Q11: Online | R11: Yes | S11: Late Delivery | T11: 0 | U11: =IF(COUNTIF(A11:A2010,A11)=1,"Keep","Duplicate") -> Keep | V11: =IF(J11<=0,"Fix","Ok") -> Fix | W11: =IF(Raw_Data!K11=0,"Missing","Valid") -> Valid | X11: =IF(C11<B11,"Dispatch Error",IF(D11<B11,"Delivery Before Order",IF(D11<C11,"Delivery Before Dispatch","OK"))) -> OK | Y11: =IF(K11<=0,"Fix","Ok") -> Ok | Z11: =IF(L11="","Blank",IF(L11=J11*K11,"Ok","Wrong")) -> Ok | AA11: =IF(OR(L11="",L11<>J11*K11),J11*K11,L11) -> -1000 | AB11: =IF(M11="","Missing","ok") -> ok | AC11: =IF(R11="No","Not Returned",IF(R11="Yes",IF(S11="","Unknown",S11),IF(L11<0,"Wrong",IF(OR(O11="Delayed",O11="In Transit",O11="On Time"),"Not Returned","")))) -> Late Delivery
A12: ORD00011 | B12: {=DATEVALUE(VLOOKUP(A12,Raw_Data!A11:D2011,{2,3,4},0))} -> 45579 | C12: 45578 | D12: 45577 | E12: Vikas Yadav | F12: Hyderabad | G12: Telangana | H12: Grocery | I12: Oil | J12: 2 | K12: 2000 | L12: =J12*K12 -> 4000 | M12: Unknown | N12: Completed | O12: Delayed | P12: WH-Pune | Q12: Online | R12: No | S12: N/A | T12: -1 | U12: =IF(COUNTIF(A12:A2011,A12)=1,"Keep","Duplicate") -> Keep | V12: =IF(J12<=0,"Fix","Ok") -> Ok | W12: =IF(Raw_Data!K12=0,"Missing","Valid") -> Valid | X12: =IF(C12<B12,"Dispatch Error",IF(D12<B12,"Delivery Before Order",IF(D12<C12,"Delivery Before Dispatch","OK"))) -> Dispatch Error | Y12: =IF(K12<=0,"Fix","Ok") -> Ok | Z12: =IF(L12="","Blank",IF(L12=J12*K12,"Ok","Wrong")) -> Ok | AA12: =IF(OR(L12="",L12<>J12*K12),J12*K12,L12) -> 4000 | AB12: =IF(M12="","Missing","ok") -> ok | AC12: =IF(R12="No","Not Returned",IF(R12="Yes",IF(S12="","Unknown",S12),IF(L12<0,"Wrong",IF(OR(O12="Delayed",O12="In Transit",O12="On Time"),"Not Returned","")))) -> Not Returned
A13: ORD00012 | B13: {=DATEVALUE(VLOOKUP(A13,Raw_Data!A12:D2012,{2,3,4},0))} -> 45465 | C13: 45463 | D13: 45464 | E13: Amit Gupta | F13: Pune | G13: Maharashtra | H13: Furniture | I13: Sofa | J13: 0 | K13: 0 | L13: =J13*K13 -> 0 | M13: Card | N13: Cancelled | O13: Delayed | P13: WH-Mumbai | Q13: Online | R13: Yes | S13: Late Delivery | T13: 1 | U13: =IF(COUNTIF(A13:A2012,A13)=1,"Keep","Duplicate") -> Keep | V13: =IF(J13<=0,"Fix","Ok") -> Fix | W13: =IF(Raw_Data!K13=0,"Missing","Valid") -> Missing | X13: =IF(C13<B13,"Dispatch Error",IF(D13<B13,"Delivery Before Order",IF(D13<C13,"Delivery Before Dispatch","OK"))) -> Dispatch Error | Y13: =IF(K13<=0,"Fix","Ok") -> Fix | Z13: =IF(L13="","Blank",IF(L13=J13*K13,"Ok","Wrong")) -> Ok | AA13: =IF(OR(L13="",L13<>J13*K13),J13*K13,L13) -> 0 | AB13: =IF(M13="","Missing","ok") -> ok | AC13: =IF(R13="No","Not Returned",IF(R13="Yes",IF(S13="","Unknown",S13),IF(L13<0,"Wrong",IF(OR(O13="Delayed",O13="In Transit",O13="On Time"),"Not Returned","")))) -> Late Delivery
... A2001: ORD02000 | B2001: {=DATEVALUE(VLOOKUP(A2001,Raw_Data!A2000:D4000,{2,3,4},0))} -> 45382 | C2001: 45385 | D2001: 45387 | E2001: Amit Joshi | F2001: Hyderabad | G2001: Telangana | H2001: Clothing | I2001: Jeans | J2001: 2 | K2001: 500 | L2001: =J2001*K2001 -> 1000 | M2001: Card | N2001: Pending | O2001: In Transit | P2001: WH-Delhi | Q2001: Online | R2001: N/A | S2001: N/A | T2001: 2 | U2001: =IF(COUNTIF(A2001:A4000,A2001)=1,"Keep","Duplicate") -> Keep | V2001: =IF(J2001<=0,"Fix","Ok") -> Ok | W2001: =IF(Raw_Data!K2001=0,"Missing","Valid") -> Valid | X2001: =IF(C2001<B2001,"Dispatch Error",IF(D2001<B2001,"Delivery Before Order",IF(D2001<C2001,"Delivery Before Dispatch","OK"))) -> OK | Y2001: =IF(K2001<=0,"Fix","Ok") -> Ok | Z2001: =IF(L2001="","Blank",IF(L2001=J2001*K2001,"Ok","Wrong")) -> Ok | AA2001: =IF(OR(L2001="",L2001<>J2001*K2001),J2001*K2001,L2001) -> 1000 | AB2001: =IF(M2001="","Missing","ok") -> ok | AC2001: =IF(R2001="No","Not Returned",IF(R2001="Yes",IF(S2001="","Unknown",S2001),IF(L2001<0,"Wrong",IF(OR(O2001="Delayed",O2001="In Transit",O2001="On Time"),"Not Returned","")))) -> Not Returned

Sheet Final_data
A1: Order_ID | B1: Order_Date | C1: Dispatch_Date | D1: Delivery_Date | E1: Customer_Name | F1: City | G1: State | H1: Product_Category | I1: Product_Name | J1: Quantity | K1: Unit_Price | L1: Total_Amount | M1: Payment_Mode | N1: Order_Status | O1: Delivery_Status | P1: Warehouse | Q1: Sales_Channel | R1: Return_Flag | S1: Return_Reason | T1: Delivery_Days | U1: Duplicate check | V1: Qty_Check_Status | W1: Unit_Price_Status | X1: Date_Status | Y1: Price_Check | Z1: Amount check | AA1: Final_Amount | AB1: Payment_Mode_check | AC1: Final_return_flag | AD1: Month | AE1: Year | AF1: Day_Name | AG1: Delivery_Performance | AH1: Delivery_Speed | AI1: Sales_Bucket | AJ1: Weekend_Order
A2: ORD00001 | B2: 45591 | C2: 45592 | D2: 45593 | E2: Karan Gupta | F2: Hyderabad | G2: Telangana | H2: Furniture | I2: Sofa | J2: 2 | K2: 100 | L2: 200 | M2: Card | N2: Pending | O2: Delayed | P2: WH-Delhi | Q2: Online | R2: No | S2: Late Delivery | T2: 1 | U2: Keep | V2: Ok | W2: Valid | X2: OK | Y2: Ok | Z2: Ok | AA2: 200 | AB2: ok | AC2: Not Returned | AD2: =TEXT(Sales_data[[#This Row],[Order_Date]],"MMM") -> Oct | AE2: =YEAR(C2) -> 2024 | AF2: =TEXT(Sales_data[[#This Row],[Order_Date]],"ddd") -> Sat | AG2: =IF(T2<=5,"On Time","Late") -> On Time | AH2: =IF(T2<=2,"Fast",IF(T2<=5,"Medium","Slow")) -> Fast | AI2: =IF(AA2>=5000,"High",IF(AA2>=2000,"Medium","Low")) -> Low | AJ2: =IF(AF2="Sat","Weekend",IF(AF2="Sun","Weekend","Weekday")) -> Weekend
A3: ORD00002 | B3: 45492 | C3: 45493 | D3: 45499 | E3: Sneha Singh | F3: Pune | G3: Maharashtra | H3: Grocery | I3: Oil | J3: 3 | K3: 2000 | L3: 6000 | M3: Card | N3: Pending | O3: On Time | P3: WH-Delhi | Q3: Offline | R3: Yes | S3: Late Delivery | T3: 6 | U3: Keep | V3: Ok | W3: Valid | X3: OK | Y3: Ok | Z3: Ok | AA3: 6000 | AB3: ok | AC3: Late Delivery | AD3: =TEXT(Sales_data[[#This Row],[Order_Date]],"MMM") -> Jul | AE3: =YEAR(C3) -> 2024 | AF3: =TEXT(Sales_data[[#This Row],[Order_Date]],"ddd") -> Fri | AG3: =IF(T3<=5,"On Time","Late") -> Late | AH3: =IF(T3<=2,"Fast",IF(T3<=5,"Medium","Slow")) -> Slow | AI3: =IF(AA3>=5000,"High",IF(AA3>=2000,"Medium","Low")) -> High | AJ3: =IF(AF3="Sat","Weekend",IF(AF3="Sun","Weekend","Weekday")) -> Weekday
A4: ORD00003 | B4: 45574 | C4: 45572 | D4: 45578 | E4: Karan Yadav | F4: Jaipur | G4: Rajasthan | H4: Furniture | I4: Table | J4: 1 | K4: 500 | L4: 500 | M4: UPI | N4: Completed | O4: Delayed | P4: WH-Pune | Q4: Online | R4: Yes | S4: Late Delivery | T4: 6 | U4: Keep | V4: Ok | W4: Valid | X4: Dispatch Error | Y4: Ok | Z4: Ok | AA4: 500 | AB4: ok | AC4: Late Delivery | AD4: =TEXT(Sales_data[[#This Row],[Order_Date]],"MMM") -> Oct | AE4: =YEAR(C4) -> 2024 | AF4: =TEXT(Sales_data[[#This Row],[Order_Date]],"ddd") -> Wed | AG4: =IF(T4<=5,"On Time","Late") -> Late | AH4: =IF(T4<=2,"Fast",IF(T4<=5,"Medium","Slow")) -> Slow | AI4: =IF(AA4>=5000,"High",IF(AA4>=2000,"Medium","Low")) -> Low | AJ4: =IF(AF4="Sat","Weekend",IF(AF4="Sun","Weekend","Weekday")) -> Weekday
A5: ORD00004 | B5: 45349 | C5: 45348 | D5: 45349 | E5: Neha Sharma | F5: Pune | G5: Maharashtra | H5: Furniture | I5: Table | J5: 1 | K5: 2000 | L5: 2000 | M5: Cash | N5: Completed | O5: Delayed | P5: WH-Delhi | Q5: Online | R5: No | S5: Late Delivery | T5: 1 | U5: Keep | V5: Ok | W5: Valid | X5: Dispatch Error | Y5: Ok | Z5: Ok | AA5: 2000 | AB5: ok | AC5: Not Returned | AD5: =TEXT(Sales_data[[#This Row],[Order_Date]],"MMM") -> Feb | AE5: =YEAR(C5) -> 2024 | AF5: =TEXT(Sales_data[[#This Row],[Order_Date]],"ddd") -> Tue | AG5: =IF(T5<=5,"On Time","Late") -> On Time | AH5: =IF(T5<=2,"Fast",IF(T5<=5,"Medium","Slow")) -> Fast | AI5: =IF(AA5>=5000,"High",IF(AA5>=2000,"Medium","Low")) -> Medium | AJ5: =IF(AF5="Sat","Weekend",IF(AF5="Sun","Weekend","Weekday")) -> Weekday
A6: ORD00005 | B6: 45502 | C6: 45503 | D6: 45503 | E6: Rahul Singh | F6: Bangalore | G6: Karnataka | H6: Clothing | I6: Jeans | J6: 1 | K6: 0 | L6: 0 | M6: Card | N6: Completed | O6: delayed | P6: WH-Delhi | Q6: Offline | R6: Yes | S6: Late Delivery | T6: 0 | U6: Keep | V6: Ok | W6: Missing | X6: OK | Y6: Fix | Z6: Ok | AA6: 0 | AB6: ok | AC6: Late Delivery | AD6: =TEXT(Sales_data[[#This Row],[Order_Date]],"MMM") -> Jul | AE6: =YEAR(C6) -> 2024 | AF6: =TEXT(Sales_data[[#This Row],[Order_Date]],"ddd") -> Mon | AG6: =IF(T6<=5,"On Time","Late") -> On Time | AH6: =IF(T6<=2,"Fast",IF(T6<=5,"Medium","Slow")) -> Fast | AI6: =IF(AA6>=5000,"High",IF(AA6>=2000,"Medium","Low")) -> Low | AJ6: =IF(AF6="Sat","Weekend",IF(AF6="Sun","Weekend","Weekday")) -> Weekday
A7: ORD00006 | B7: 45468 | C7: 45468 | D7: 45472 | E7: Vikas Joshi | F7: Jaipur | G7: Rajasthan | H7: Grocery | I7: Rice | J7: -1 | K7: 500 | L7: -500 | M7: Cash | N7: Completed | O7: In Transit | P7: WH-Delhi | Q7: Online | R7: No | S7: Late Delivery | T7: 4 | U7: Keep | V7: Fix | W7: Valid | X7: OK | Y7: Ok | Z7: Ok | AA7: -500 | AB7: ok | AC7: Not Returned | AD7: =TEXT(Sales_data[[#This Row],[Order_Date]],"MMM") -> Jun | AE7: =YEAR(C7) -> 2024 | AF7: =TEXT(Sales_data[[#This Row],[Order_Date]],"ddd") -> Tue | AG7: =IF(T7<=5,"On Time","Late") -> On Time | AH7: =IF(T7<=2,"Fast",IF(T7<=5,"Medium","Slow")) -> Medium | AI7: =IF(AA7>=5000,"High",IF(AA7>=2000,"Medium","Low")) -> Low | AJ7: =IF(AF7="Sat","Weekend",IF(AF7="Sun","Weekend","Weekday")) -> Weekday
A8: ORD00007 | B8: 45296 | C8: 45298 | D8: 45299 | E8: Karan Yadav | F8: Jaipur | G8: Rajasthan | H8: Furniture | I8: Chair | J8: 0 | K8: 2000 | L8: 0 | M8: UPI | N8: Completed | O8: Delayed | P8: WH-Mumbai | Q8: Online | R8: No | S8: Late Delivery | T8: 1 | U8: Keep | V8: Fix | W8: Valid | X8: OK | Y8: Ok | Z8: Ok | AA8: 0 | AB8: ok | AC8: Not Returned | AD8: =TEXT(Sales_data[[#This Row],[Order_Date]],"MMM") -> Jan | AE8: =YEAR(C8) -> 2024 | AF8: =TEXT(Sales_data[[#This Row],[Order_Date]],"ddd") -> Fri | AG8: =IF(T8<=5,"On Time","Late") -> On Time | AH8: =IF(T8<=2,"Fast",IF(T8<=5,"Medium","Slow")) -> Fast | AI8: =IF(AA8>=5000,"High",IF(AA8>=2000,"Medium","Low")) -> Low | AJ8: =IF(AF8="Sat","Weekend",IF(AF8="Sun","Weekend","Weekday")) -> Weekday
A9: ORD00008 | B9: 45612 | C9: 45614 | D9: 45616 | E9: Sneha Patel | F9: Nagpur | G9: Maharashtra | H9: Clothing | I9: T-Shirt | J9: 1 | K9: 0 | L9: 0 | M9: Card | N9: Cancelled | O9: On Time | P9: WH-Pune | Q9: Online | R9: yes | S9: Late Delivery | T9: 2 | U9: Keep | V9: Ok | W9: Missing | X9: OK | Y9: Fix | Z9: Ok | AA9: 0 | AB9: ok | AC9: Late Delivery | AD9: =TEXT(Sales_data[[#This Row],[Order_Date]],"MMM") -> Nov | AE9: =YEAR(C9) -> 2024 | AF9: =TEXT(Sales_data[[#This Row],[Order_Date]],"ddd") -> Sat | AG9: =IF(T9<=5,"On Time","Late") -> On Time | AH9: =IF(T9<=2,"Fast",IF(T9<=5,"Medium","Slow")) -> Fast | AI9: =IF(AA9>=5000,"High",IF(AA9>=2000,"Medium","Low")) -> Low | AJ9: =IF(AF9="Sat","Weekend",IF(AF9="Sun","Weekend","Weekday")) -> Weekend
A10: ORD00009 | B10: 45346 | C10: 45344 | D10: 45349 | E10: Rahul Joshi | F10: Bangalore | G10: Karnataka | H10: Clothing | I10: T-Shirt | J10: 2 | K10: 100 | L10: 200 | M10: UPI | N10: Completed | O10: On Time | P10: WH-Pune | Q10: Online | R10: yes | S10: Late Delivery | T10: 5 | U10: Keep | V10: Ok | W10: Valid | X10: Dispatch Error | Y10: Ok | Z10: Ok | AA10: 200 | AB10: ok | AC10: Late Delivery | AD10: =TEXT(Sales_data[[#This Row],[Order_Date]],"MMM") -> Feb | AE10: =YEAR(C10) -> 2024 | AF10: =TEXT(Sales_data[[#This Row],[Order_Date]],"ddd") -> Sat | AG10: =IF(T10<=5,"On Time","Late") -> On Time | AH10: =IF(T10<=2,"Fast",IF(T10<=5,"Medium","Slow")) -> Medium | AI10: =IF(AA10>=5000,"High",IF(AA10>=2000,"Medium","Low")) -> Low | AJ10: =IF(AF10="Sat","Weekend",IF(AF10="Sun","Weekend","Weekday")) -> Weekend
A11: ORD00010 | B11: 45641 | C11: 45644 | D11: 45644 | E11: Rahul Singh | F11: Pune | G11: Maharashtra | H11: Furniture | I11: Sofa | J11: -1 | K11: 1000 | L11: -1000 | M11: Unknown | N11: Completed | O11: Delayed | P11: WH-Pune | Q11: Online | R11: Yes | S11: Late Delivery | T11: 0 | U11: Keep | V11: Fix | W11: Valid | X11: OK | Y11: Ok | Z11: Ok | AA11: -1000 | AB11: ok | AC11: Late Delivery | AD11: =TEXT(Sales_data[[#This Row],[Order_Date]],"MMM") -> Dec | AE11: =YEAR(C11) -> 2024 | AF11: =TEXT(Sales_data[[#This Row],[Order_Date]],"ddd") -> Sun | AG11: =IF(T11<=5,"On Time","Late") -> On Time | AH11: =IF(T11<=2,"Fast",IF(T11<=5,"Medium","Slow")) -> Fast | AI11: =IF(AA11>=5000,"High",IF(AA11>=2000,"Medium","Low")) -> Low | AJ11: =IF(AF11="Sat","Weekend",IF(AF11="Sun","Weekend","Weekday")) -> Weekend
A12: ORD00011 | B12: 45579 | C12: 45578 | D12: 45577 | E12: Vikas Yadav | F12: Hyderabad | G12: Telangana | H12: Grocery | I12: Oil | J12: 2 | K12: 2000 | L12: 4000 | M12: Unknown | N12: Completed | O12: Delayed | P12: WH-Pune | Q12: Online | R12: No | S12: N/A | T12: -1 | U12: Keep | V12: Ok | W12: Valid | X12: Dispatch Error | Y12: Ok | Z12: Ok | AA12: 4000 | AB12: ok | AC12: Not Returned | AD12: =TEXT(Sales_data[[#This Row],[Order_Date]],"MMM") -> Oct | AE12: =YEAR(C12) -> 2024 | AF12: =TEXT(Sales_data[[#This Row],[Order_Date]],"ddd") -> Mon | AG12: =IF(T12<=5,"On Time","Late") -> On Time | AH12: =IF(T12<=2,"Fast",IF(T12<=5,"Medium","Slow")) -> Fast | AI12: =IF(AA12>=5000,"High",IF(AA12>=2000,"Medium","Low")) -> Medium | AJ12: =IF(AF12="Sat","Weekend",IF(AF12="Sun","Weekend","Weekday")) -> Weekday
A13: ORD00012 | B13: 45465 | C13: 45463 | D13: 45464 | E13: Amit Gupta | F13: Pune | G13: Maharashtra | H13: Furniture | I13: Sofa | J13: 0 | K13: 0 | L13: 0 | M13: Card | N13: Cancelled | O13: Delayed | P13: WH-Mumbai | Q13: Online | R13: Yes | S13: Late Delivery | T13: 1 | U13: Keep | V13: Fix | W13: Missing | X13: Dispatch Error | Y13: Fix | Z13: Ok | AA13: 0 | AB13: ok | AC13: Late Delivery | AD13: =TEXT(Sales_data[[#This Row],[Order_Date]],"MMM") -> Jun | AE13: =YEAR(C13) -> 2024 | AF13: =TEXT(Sales_data[[#This Row],[Order_Date]],"ddd") -> Sat | AG13: =IF(T13<=5,"On Time","Late") -> On Time | AH13: =IF(T13<=2,"Fast",IF(T13<=5,"Medium","Slow")) -> Fast | AI13: =IF(AA13>=5000,"High",IF(AA13>=2000,"Medium","Low")) -> Low | AJ13: =IF(AF13="Sat","Weekend",IF(AF13="Sun","Weekend","Weekday")) -> Weekend
... A2001: ORD02000 | B2001: 45382 | C2001: 45385 | D2001: 45387 | E2001: Amit Joshi | F2001: Hyderabad | G2001: Telangana | H2001: Clothing | I2001: Jeans | J2001: 2 | K2001: 500 | L2001: 1000 | M2001: Card | N2001: Pending | O2001: In Transit | P2001: WH-Delhi | Q2001: Online | R2001: N/A | S2001: N/A | T2001: 2 | U2001: Keep | V2001: Ok | W2001: Valid | X2001: OK | Y2001: Ok | Z2001: Ok | AA2001: 1000 | AB2001: ok | AC2001: Not Returned | AD2001: =TEXT(Sales_data[[#This Row],[Order_Date]],"MMM") -> Mar | AE2001: =YEAR(C2001) -> 2024 | AF2001: =TEXT(Sales_data[[#This Row],[Order_Date]],"ddd") -> Sun | AG2001: =IF(T2001<=5,"On Time","Late") -> On Time | AH2001: =IF(T2001<=2,"Fast",IF(T2001<=5,"Medium","Slow")) -> Fast | AI2001: =IF(AA2001>=5000,"High",IF(AA2001>=2000,"Medium","Low")) -> Low | AJ2001: =IF(AF2001="Sat","Weekend",IF(AF2001="Sun","Weekend","Weekday")) -> Weekend

Sheet Pivote_data
A2: Monthly revenue
A3: Months | B3: Final Amount
A4: Feb | B4: 3700
A5: Mar | B5: 21300
A6: Apr | B6: 8800
A7: Jul | B7: 11500
A8: Aug | B8: 26200
A9: Oct | B9: 17600
A10: Dec | B10: 14300
A11: Grand Total | B11: 103400
A18: Revenue by Product Category
A19: Product category | B19: Final_Amount
A20: Furniture | B20: 103400
A21: Grand Total | B21: 103400
A28: Orders by State
A29: Row Labels | B29: Count of Order_ID
A30: Delhi | B30: 24
A31: Karnataka | B31: 20
A32: Maharashtra | B32: 48
A33: Rajasthan | B33: 7
A34: Telangana | B34: 15
A35: Uttar Pradesh | B35: 16
A36: Grand Total | B36: 130
A39: Payment Mode
A40: Row Labels | B40: Count of Order_ID
A41: Card | B41: 57
A42: UPI | B42: 73
A43: Grand Total | B43: 130
A48: Delivery Performance
A49: Row Labels | B49: Count of Order_ID
A50: Late | B50: 31
A51: On Time | B51: 99
A52: Grand Total | B52: 130
A57: Sales Bucket
A58: Row Labels | B58: Count of Order_ID
A59: High | B59: 5
A60: Low | B60: 103
A61: Medium | B61: 22
A62: Grand Total | B62: 130

Sheet Dashboard
Q5: =COUNTIF(Sales_data[[#All],[Delivery_Performance]],"On Time")/COUNTA(Sales_data[Order_ID]) -> 0.7745
G6: =COUNTA(Sales_data[Order_ID]) -> 2000 | I6: =SUM(Sales_data[Final_Amount]) -> 1417100 | L6: =SUM(Sales_data[Quantity]) -> 2024
N8: =AVERAGE(Sales_data[Delivery_Days]) -> 3.033
